Workbook

Sheet Compliance Assessment
A1: Axiom AI Technologies — Compliance Assessment Workbook (AAX-COMP-2026-001)
A2: Primary framework: ISO/IEC 27001:2022 | Supporting: NIST CSF 2.0, NIST SP 800-53 | Status: In Progress | Simulated portfolio case study
A4: Requirement ID | B4: Framework | C4: Reference | D4: Domain | E4: Requirement | F4: Axiom Control / Process | G4: Related Policy / Artifact | H4: Evidence | I4: Evidence Rating | J4: Compliance Status | K4: Risk Rating | L4: Control Owner | M4: Gap / Observation | N4: Remediation Required | O4: Target Date | P4: Validation Status | Q4: Notes
A5: ISO/IEC 27001:2022 Requirements (Clauses 4–9)
A6: ISO-01 | B6: ISO 27001 | C6: Clause 4.1 | D6: Context | E6: The organization identifies internal and external issues relevant to the ISMS. | F6: ISMS Context Management | G6: ISMS Scope Statement | H6: Documented organizational context and ISMS scope | I6: Strong | J6: Compliant | K6: Low | L6: ISMS Owner | M6: No significant gap identified. | N6: No | O6: 46661 | P6: Validated | Q6: Review annually and following significant organizational changes.
A7: ISO-02 | B7: ISO 27001 | C7: Clause 4.2 | D7: Interested Parties | E7: Relevant interested parties and their information-security requirements are identified. | F7: Interested Party Management | G7: ISMS Scope Statement; Stakeholder Requirements | H7: Customer, employee, regulatory, supplier, and management requirements | I7: Adequate | J7: Compliant | K7: Low | L7: ISMS Owner | M7: Stakeholder requirements are documented but should be reviewed alongside contractual changes. | N7: No | O7: 46661 | P7: Validated | Q7: Include regulatory and contractual requirements in annual review.
A8: ISO-03 | B8: ISO 27001 | C8: Clause 4.3 | D8: ISMS Scope | E8: The organization determines the boundaries and applicability of the ISMS. | F8: ISMS Scope Management | G8: ISMS Scope Statement | H8: Approved ISMS scope statement | I8: Strong | J8: Compliant | K8: Low | L8: ISMS Owner | M8: No material gap identified. | N8: No | O8: 46661 | P8: Validated | Q8: Scope must be reassessed after material business or technology changes.
A9: ISO-04 | B9: ISO 27001 | C9: Clause 5.1 | D9: Leadership | E9: Leadership demonstrates commitment to the ISMS. | F9: Management Oversight | G9: Security Governance Framework; Management Review | H9: Governance records and management review documentation | I9: Adequate | J9: Partially Compliant | K9: Moderate | L9: Executive Management | M9: Management oversight exists, but governance decisions are not consistently centralized. | N9: Yes | O9: 46418 | P9: In Progress | Q9: Establish a centralized governance decision and action log.
A10: ISO-05 | B10: ISO 27001 | C10: Clause 5.2 | D10: Policy | E10: An information-security policy is established, implemented, maintained, and communicated. | F10: Security Policy Management | G10: Information Security Policy | H10: Approved information-security policy | I10: Strong | J10: Compliant | K10: Low | L10: ISMS Owner | M10: Policy framework is established. | N10: No | O10: 46661 | P10: Validated | Q10: Annual policy review required.
A11: ISO-06 | B11: ISO 27001 | C11: Clause 5.3 | D11: Roles and Responsibilities | E11: Roles, responsibilities, and authorities relevant to information security are assigned. | F11: Security Roles and Responsibilities | G11: Roles & Responsibilities; Security Governance Framework | H11: Defined governance and control ownership structure | I11: Adequate | J11: Partially Compliant | K11: Moderate | L11: ISMS Owner | M11: Core responsibilities are assigned, but some supporting control ownership requires further formalization. | N11: Yes | O11: 46446 | P11: In Progress | Q11: Complete control-owner mapping.
A12: ISO-07 | B12: ISO 27001 | C12: Clause 6.1 | D12: Risk Management | E12: Information-security risks and opportunities are addressed through a defined process. | F12: Information Security Risk Management | G12: Risk Register; Risk Assessment | H12: Risk register and risk treatment records | I12: Strong | J12: Compliant | K12: Low | L12: Security/GRC | M12: Risk management process is established. | N12: No | O12: 46661 | P12: Validated | Q12: Continue periodic risk reassessment.
A13: ISO-08 | B13: ISO 27001 | C13: Clause 6.2 | D13: Security Objectives | E13: Information-security objectives are established and monitored. | F13: Security Objectives Management | G13: Security Objectives; KPI/KRI Dashboard | H13: Defined objectives and management metrics | I13: Adequate | J13: Partially Compliant | K13: Moderate | L13: ISMS Owner | M13: Objectives exist but measurement consistency requires improvement. | N13: Yes | O13: 46477 | P13: In Progress | Q13: Establish consistent objective owners and reporting frequency.
A14: ISO-09 | B14: ISO 27001 | C14: Clause 7.2 | D14: Competence | E14: Persons performing work affecting information security are competent. | F14: Security Competency Management | G14: Security Awareness and Training Records | H14: Training records and role-based competency requirements | I14: Adequate | J14: Compliant | K14: Low | L14: HR / Security | M14: Training framework is established. | N14: No | O14: 46661 | P14: Validated | Q14: Continue role-based training.
A15: ISO-10 | B15: ISO 27001 | C15: Clause 7.3 | D15: Awareness | E15: Personnel are aware of relevant information-security policies and their responsibilities. | F15: Security Awareness | G15: Information Security Policy; Security Awareness Program | H15: Security awareness materials and training records | I15: Adequate | J15: Compliant | K15: Low | L15: Security/GRC | M15: No significant gap identified. | N15: No | O15: 46661 | P15: Validated | Q15: Maintain annual awareness activities.
A16: ISO-11 | B16: ISO 27001 | C16: Clause 7.5 | D16: Documented Information | E16: Required documented information is controlled and maintained. | F16: Document Control | G16: Document Control Process; ISMS Repository | H16: Version-controlled ISMS documentation | I16: Strong | J16: Compliant | K16: Low | L16: ISMS Owner | M16: Document control process is established. | N16: No | O16: 46661 | P16: Validated | Q16: Continue controlled document review.
A17: ISO-12 | B17: ISO 27001 | C17: Clause 8.1 | D17: Operational Planning | E17: Operational processes required to meet information-security requirements are planned and controlled. | F17: Security Operations Management | G17: Vulnerability Management; Incident Response; Access Control | H17: Operational procedures and security-process records | I17: Adequate | J17: Partially Compliant | K17: Moderate | L17: Security Operations | M17: Processes exist but evidence consistency varies between operational activities. | N17: Yes | O17: 46477 | P17: In Progress | Q17: Standardize operational evidence collection.
... A21: ISO-16 | B21: ISO 27001 | C21: Clause 9.2 | D21: Internal Audit | E21: Internal audits are conducted at planned intervals. | F21: Internal Assessment | G21: Internal Audit Program | H21: Assessment plan, findings, and corrective actions | I21: Adequate | J21: Partially Compliant | K21: Moderate | L21: Internal Audit / ISMS Owner | M21: Assessment process is defined but recurring independent assessment evidence should be strengthened. | N21: Yes | O21: 46538 | P21: Not Started | Q21: Establish annual internal audit schedule.
A22: ISO/IEC 27001 Annex A Controls
A23: A-01 | B23: ISO 27001 | C23: A.5.1 | D23: Organizational Controls | E23: Policies for information security are defined, approved, communicated, and reviewed. | F23: Security Policy Management | G23: Information Security Policy | H23: Approved policy and review records | I23: Strong | J23: Compliant | K23: Low | L23: ISMS Owner | M23: No significant gap. | N23: No | O23: 46661 | P23: Validated | Q23: Annual review required.
A24: A-02 | B24: ISO 27001 | C24: A.5.15 | D24: Access Control | E24: Rules for controlling physical and logical access are established and implemented. | F24: Access Management | G24: Access Control Policy | H24: Access-control procedures and user-access records | I24: Adequate | J24: Partially Compliant | K24: Moderate | L24: IT / Security | M24: Access processes exist but periodic review evidence requires strengthening. | N24: Yes | O24: 46446 | P24: In Progress | Q24: Formalize recurring access-review evidence.
A25: A-03 | B25: ISO 27001 | C25: A.5.18 | D25: Access Rights | E25: Access rights are provisioned, reviewed, modified, and removed according to defined processes. | F25: User Access Lifecycle | G25: Access Control Policy | H25: Provisioning, review, and termination records | I25: Adequate | J25: Partially Compliant | K25: Moderate | L25: IT / Security | M25: Review frequency and evidence retention require further standardization. | N25: Yes | O25: 46446 | P25: In Progress | Q25: Implement documented quarterly access reviews.
A26: A-04 | B26: ISO 27001 | C26: A.5.24 | D26: Incident Management | E26: Incident-management planning and preparation are established. | F26: Incident Response | G26: Incident Response Policy | H26: Incident-response procedures and tabletop exercise | I26: Strong | J26: Compliant | K26: Low | L26: Security Operations | M26: No significant gap. | N26: No | O26: 46661 | P26: Validated | Q26: Continue periodic exercises.
A27: A-05 | B27: ISO 27001 | C27: A.5.25 | D27: Incident Assessment | E27: Information-security events are assessed to determine whether they constitute incidents. | F27: Incident Triage | G27: Incident Response Policy | H27: Incident classification and triage procedures | I27: Adequate | J27: Compliant | K27: Low | L27: Security Operations | M27: Process is defined. | N27: No | O27: 46661 | P27: Validated | Q27: Maintain incident classification criteria.
A28: A-06 | B28: ISO 27001 | C28: A.5.26 | D28: Incident Response | E28: Information-security incidents are responded to according to documented procedures. | F28: Incident Response Management | G28: Incident Response Policy | H28: Incident procedures, escalation records, and tabletop results | I28: Strong | J28: Compliant | K28: Low | L28: Security Operations | M28: No significant gap. | N28: No | O28: 46661 | P28: Validated | Q28: Continue periodic testing.
A29: A-07 | B29: ISO 27001 | C29: A.5.28 | D29: Evidence Collection | E29: Procedures for identification, collection, acquisition, and preservation of evidence are established. | F29: Security Evidence Management | G29: Incident Response; Evidence Register | H29: Evidence-handling procedures and investigation records | I29: Limited | J29: Partially Compliant | K29: Moderate | L29: Security Operations | M29: Evidence-handling expectations require further formalization. | N29: Yes | O29: 46507 | P29: Not Started | Q29: Formalize evidence-handling and retention requirements.
A30: A-08 | B30: ISO 27001 | C30: A.5.30 | D30: Business Continuity | E30: ICT readiness for business continuity is established. | F30: ICT Continuity Management | G30: BIA; BCP/DR Strategy; DRP | H30: RTO/RPO requirements, recovery strategies, and recovery runbooks | I30: Strong | J30: Compliant | K30: Low | L30: Business Continuity / IT | M30: No significant gap. | N30: No | O30: 46661 | P30: Validated | Q30: Continue tabletop and recovery testing.
A31: A-09 | B31: ISO 27001 | C31: A.8.8 | D31: Technical Vulnerability Management | E31: Technical vulnerabilities are identified, evaluated, and addressed. | F31: Vulnerability Management | G31: Vulnerability Management Program | H31: Vulnerability register, remediation records, and risk ratings | I31: Strong | J31: Compliant | K31: Low | L31: Security Operations | M31: Vulnerability-management process is established. | N31: No | O31: 46661 | P31: Validated | Q31: Continue risk-based remediation.
A32: A-10 | B32: ISO 27001 | C32: A.8.15 | D32: Logging and Monitoring | E32: Logs are generated, protected, and reviewed for relevant systems and activities. | F32: Security Logging and Monitoring | G32: Logging and Monitoring Procedures | H32: Cloud logging, monitoring records, and alerting processes | I32: Adequate | J32: Partially Compliant | K32: Moderate | L32: Security Operations | M32: Logging exists, but centralized review and evidence retention should be strengthened. | N32: Yes | O32: 46538 | P32: In Progress | Q32: Improve centralized monitoring evidence.
A33: A-11 | B33: ISO 27001 | C33: A.5.31 | D33: Legal and Regulatory Compliance | E33: Legal, statutory, regulatory, and contractual information-security requirements are identified and maintained. | F33: Compliance Requirements Management | G33: Compliance Register; Privacy Program | H33: Regulatory and contractual requirements register | I33: Adequate | J33: Partially Compliant | K33: Moderate | L33: Legal / Security/GRC | M33: Core requirements are identified, but centralized tracking should be improved. | N33: Yes | O33: 46477 | P33: In Progress | Q33: Establish formal compliance obligations register.
A34: A-12 | B34: ISO 27001 | C34: A.5.36 | D34: Security Compliance | E34: Compliance with information-security policies, rules, and standards is regularly reviewed. | F34: Policy Compliance Monitoring | G34: Compliance Assessment; Internal Audit Program | H34: Compliance assessments and corrective-action records | I34: Adequate | J34: Partially Compliant | K34: Moderate | L34: Security/GRC | M34: Assessment activities exist but recurring compliance validation needs formal scheduling. | N34: Yes | O34: 46538 | P34: Not Started | Q34: Establish recurring control-compliance review cycle.
A35: NIST CSF 2.0 / Supporting Requirements
A36: NIST-01 | B36: NIST CSF 2.0 | C36: GV.OC | D36: Govern | E36: Organizational context is understood and used to establish cybersecurity risk-management priorities. | F36: Governance and Organizational Context | G36: Security Governance Framework | H36: Governance framework and ISMS scope | I36: Strong | J36: Compliant | K36: Low | L36: ISMS Owner | M36: No significant gap. | N36: No | O36: 46661 | P36: Validated | Q36: Review after significant organizational change.
A37: NIST-02 | B37: NIST CSF 2.0 | C37: GV.RR | D37: Govern | E37: Cybersecurity roles, responsibilities, and authorities are established and communicated. | F37: Governance Roles and Responsibilities | G37: Security Governance Framework | H37: Governance structure and responsibility matrix | I37: Adequate | J37: Partially Compliant | K37: Moderate | L37: ISMS Owner | M37: Some control ownership requires additional formalization. | N37: Yes | O37: 46446 | P37: In Progress | Q37: Complete ownership mapping.
A38: NIST-03 | B38: NIST CSF 2.0 | C38: GV.PO | D38: Govern | E38: Cybersecurity policy is established, communicated, and maintained. | F38: Security Policy Governance | G38: Information Security Policy | H38: Approved security policies | I38: Strong | J38: Compliant | K38: Low | L38: ISMS Owner | M38: No significant gap. | N38: No | O38: 46661 | P38: Validated | Q38: Annual review required.
A39: NIST-04 | B39: NIST CSF 2.0 | C39: ID.AM | D39: Identify | E39: Assets, services, systems, and relevant resources are identified and managed. | F39: Asset Management | G39: Asset Management Policy; Asset Inventory | H39: Asset inventory and ownership information | I39: Adequate | J39: Partially Compliant | K39: Moderate | L39: IT / Security | M39: Asset inventory requires continued completeness validation. | N39: Yes | O39: 46477 | P39: In Progress | Q39: Perform periodic inventory reconciliation.
A40: NIST-05 | B40: NIST CSF 2.0 | C40: ID.RA | D40: Identify | E40: Cybersecurity risks are identified, analyzed, and prioritized. | F40: Cyber Risk Assessment | G40: Risk Register; Risk Assessment | H40: Risk register and risk treatment decisions | I40: Strong | J40: Compliant | K40: Low | L40: Security/GRC | M40: No significant gap. | N40: No | O40: 46661 | P40: Validated | Q40: Continue periodic risk assessments.
A41: NIST-06 | B41: NIST CSF 2.0 | C41: PR.AA | D41: Protect | E41: Identities and access permissions are managed according to risk. | F41: Identity and Access Management | G41: Access Control Policy | H41: Identity-management and access-review records | I41: Adequate | J41: Partially Compliant | K41: Moderate | L41: IT / Security | M41: Access review evidence requires further standardization. | N41: Yes | O41: 46446 | P41: In Progress | Q41: Establish recurring access certification.
A42: NIST-07 | B42: NIST CSF 2.0 | C42: PR.AT | D42: Protect | E42: Personnel receive cybersecurity awareness and training appropriate to their roles. | F42: Security Awareness and Training | G42: Security Awareness Program | H42: Training records and awareness materials | I42: Adequate | J42: Compliant | K42: Low | L42: HR / Security | M42: No significant gap. | N42: No | O42: 46661 | P42: Validated | Q42: Continue annual awareness training.
A43: NIST-08 | B43: NIST CSF 2.0 | C43: DE.CM | D43: Detect | E43: Systems and assets are monitored to identify potentially adverse events. | F43: Security Monitoring | G43: Logging and Monitoring Procedures | H43: Cloud monitoring, alerts, and security-event records | I43: Adequate | J43: Partially Compliant | K43: Moderate | L43: Security Operations | M43: Monitoring exists but centralized evidence and review processes require improvement. | N43: Yes | O43: 46538 | P43: In Progress | Q43: Improve centralized monitoring and review evidence.
A44: NIST-09 | B44: NIST CSF 2.0 | C44: RS.MA | D44: Respond | E44: Incident response activities are managed and coordinated according to established procedures. | F44: Incident Response Management | G44: Incident Response Policy | H44: Incident-response procedures and tabletop exercise | I44: Strong | J44: Compliant | K44: Low | L44: Security Operations | M44: No significant gap. | N44: No | O44: 46661 | P44: Validated | Q44: Continue periodic exercises.
...

Sheet Summary Dashboard
A1: Summary Dashboard
A2: All counts are live formulas driven by the 'Compliance Assessment' sheet.
A4: Metric | B4: Value
A5: Total Requirements | B5: =COUNTA('Compliance Assessment'!$B$5:$B$47) -> 40
A6: Compliant | B6: =COUNTIF('Compliance Assessment'!$J$5:$J$47,"Compliant") -> 23
A7: Partially Compliant | B7: =COUNTIF('Compliance Assessment'!$J$5:$J$47,"Partially Compliant") -> 17
A8: Non-Compliant | B8: =COUNTIF('Compliance Assessment'!$J$5:$J$47,"Non-Compliant") -> 0
A9: Not Applicable | B9: =COUNTIF('Compliance Assessment'!$J$5:$J$47,"Not Applicable") -> 0
A10: Under Review | B10: =COUNTIF('Compliance Assessment'!$J$5:$J$47,"Under Review") -> 0
A11: Strong Evidence | B11: =COUNTIF('Compliance Assessment'!$I$5:$I$47,"Strong") -> 18
A12: Adequate Evidence | B12: =COUNTIF('Compliance Assessment'!$I$5:$I$47,"Adequate") -> 21
A13: Limited Evidence | B13: =COUNTIF('Compliance Assessment'!$I$5:$I$47,"Limited") -> 1
A14: Missing Evidence | B14: =COUNTIF('Compliance Assessment'!$I$5:$I$47,"Missing") -> 0
A15: Critical Risk | B15: =COUNTIF('Compliance Assessment'!$K$5:$K$47,"Critical") -> 0
A16: High Risk | B16: =COUNTIF('Compliance Assessment'!$K$5:$K$47,"High") -> 0
A17: Moderate Risk | B17: =COUNTIF('Compliance Assessment'!$K$5:$K$47,"Moderate") -> 17
A18: Low Risk | B18: =COUNTIF('Compliance Assessment'!$K$5:$K$47,"Low") -> 23
A19: Remediation Required | B19: =COUNTIF('Compliance Assessment'!$N$5:$N$47,"Yes") -> 17
A20: Remediation Not Required | B20: =COUNTIF('Compliance Assessment'!$N$5:$N$47,"No") -> 23
A21: Validated | B21: =COUNTIF('Compliance Assessment'!$P$5:$P$47,"Validated") -> 23
A22: In Progress | B22: =COUNTIF('Compliance Assessment'!$P$5:$P$47,"In Progress") -> 14
A23: Not Started | B23: =COUNTIF('Compliance Assessment'!$P$5:$P$47,"Not Started") -> 3
A25: Key Metrics
A26: Metric | B26: Value
A27: Overall Compliance Rate | B27: =IF($B$5=0,0,B6/$B$5) -> 0.575
A28: Partial Compliance Rate | B28: =IF($B$5=0,0,B7/$B$5) -> 0.425
A29: Non-Compliance Rate | B29: =IF($B$5=0,0,B8/$B$5) -> 0
A30: Evidence Coverage (not Missing) | B30: =IF($B$5=0,0,($B$5-B14)/$B$5) -> 1
A31: Validated Requirement Rate | B31: =IF($B$5=0,0,B21/$B$5) -> 0.575
A33: Management Interpretation
A34: The assessment indicates that Axiom has established a substantial baseline of information-security governance and operational controls. The primary improvement opportunities involve formalizing recurring governance evidence, strengthening access-review evidence, improving centralized monitoring, formalizing compliance-obligation tracking, and establishing more consistent performance evaluation. No critical or high-risk compliance gaps were identified in this simulated assessment. Moderate findings should nevertheless be tracked through the remediation process and reported to management until validated.

Sheet Findings & Remediation
A1: Finding ID | B1: Source | C1: Finding | D1: Risk | E1: Owner | F1: Remediation | G1: Target Date | H1: Status
A2: F-001 | B2: ISO-04 | C2: Governance decisions are not consistently centralized. | D2: Moderate | E2: Executive Management | F2: Establish governance decision/action log. | G2: 46418 | H2: In Progress
A3: F-002 | B3: ISO-06 | C3: Some control ownership requires formalization. | D3: Moderate | E3: ISMS Owner | F3: Complete control-owner mapping. | G3: 46446 | H3: In Progress
A4: F-003 | B4: ISO-08 | C4: Security-objective measurement requires greater consistency. | D4: Moderate | E4: ISMS Owner | F4: Define owners, metrics, and reporting frequency. | G4: 46477 | H4: In Progress
A5: F-004 | B5: ISO-12 | C5: Operational evidence collection varies between processes. | D5: Moderate | E5: Security Operations | F5: Standardize operational evidence requirements. | G5: 46477 | H5: In Progress
A6: F-005 | B6: ISO-15 | C6: Metrics lack consistent trend analysis. | D6: Moderate | E6: ISMS Owner | F6: Implement recurring trend reporting. | G6: 46507 | H6: In Progress
A7: F-006 | B7: ISO-16 | C7: Recurring independent assessment evidence should be strengthened. | D7: Moderate | E7: Internal Audit | F7: Establish annual internal audit schedule. | G7: 46538 | H7: Not Started
A8: F-007 | B8: A-02 | C8: Access-review evidence requires strengthening. | D8: Moderate | E8: IT / Security | F8: Formalize recurring access reviews. | G8: 46446 | H8: In Progress
A9: F-008 | B9: A-03 | C9: Access lifecycle review frequency requires standardization. | D9: Moderate | E9: IT / Security | F9: Implement quarterly access reviews. | G9: 46446 | H9: In Progress
A10: F-009 | B10: A-07 | C10: Evidence-handling requirements require formalization. | D10: Moderate | E10: Security Operations | F10: Document evidence-handling and retention requirements. | G10: 46507 | H10: Not Started
A11: F-010 | B11: A-10 | C11: Centralized logging and monitoring evidence should be strengthened. | D11: Moderate | E11: Security Operations | F11: Improve centralized monitoring evidence. | G11: 46538 | H11: In Progress
A12: F-011 | B12: A-11 | C12: Compliance-obligation tracking should be centralized. | D12: Moderate | E12: Legal / Security/GRC | F12: Establish compliance obligations register. | G12: 46477 | H12: In Progress
A13: F-012 | B13: A-12 | C13: Recurring policy-compliance validation needs formal scheduling. | D13: Moderate | E13: Security/GRC | F13: Establish recurring compliance review cycle. | G13: 46538 | H13: Not Started
... A19: F-018 | B19: ISO-07 | C19: Continue periodic risk reassessment and treatment monitoring. | D19: Low | E19: Security/GRC | F19: Continue existing risk-management cycle. | G19: 46661 | H19: Validated

Sheet Framework Mapping
A1: ISO / Axiom Area | B1: NIST CSF | C1: Axiom Control Area | D1: Portfolio Project
A2: ISMS Context | B2: GV.OC | C2: Governance / ISMS Scope | D2: P3
A3: Leadership | B3: GV.RR / GV.PO | C3: Security Governance | D3: P6
A4: Risk Management | B4: ID.RA | C4: Cyber Risk Management | D4: P1
A5: Asset Management | B5: ID.AM | C5: Asset Management | D5: P2 / P6
A6: Access Control | B6: PR.AA | C6: Identity and Access Management | D6: P2
A7: Security Awareness | B7: PR.AT | C7: Security Awareness | D7: P3 / P6
A8: Vulnerability Management | B8: ID.RA / PR.PS | C8: Vulnerability Management | D8: P5
A9: Security Monitoring | B9: DE.CM | C9: Logging and Monitoring | D9: P5 / P6
A10: Incident Response | B10: RS.MA | C10: Incident Management | D10: P3 / P5
A11: Malware Analysis | B11: RS.AN | C11: Security Investigation | D11: P5
A12: Business Continuity | B12: RC.RP | C12: BCP / DR | D12: P4
... A19: Data Security | B19: PR.DS | C19: Data Protection | D19: P2 / P6

Sheet Evidence Register
A1: Evidence ID | B1: Evidence | C1: Related Requirement / Finding | D1: Evidence Type | E1: Rating | F1: Owner
A2: EV-001 | B2: ISMS Scope Statement | C2: ISO-01, ISO-03, NIST-01 | D2: Governance | E2: Strong | F2: ISMS Owner
A3: EV-002 | B3: Information Security Policy | C3: ISO-05, A-01, NIST-03 | D3: Policy | E3: Strong | F3: ISMS Owner
A4: EV-003 | B4: Security Governance Framework | C4: ISO-04, ISO-06, NIST-02 | D4: Governance | E4: Adequate | F4: ISMS Owner
A5: EV-004 | B5: Risk Register | C5: ISO-07, ISO-13, ISO-14, NIST-05, NIST-11 | D5: Risk | E5: Strong | F5: Security/GRC
A6: EV-005 | B6: Security Objectives / KPI Dashboard | C6: ISO-08, ISO-15 | D6: Metrics | E6: Adequate | F6: ISMS Owner
A7: EV-006 | B7: Security Awareness Records | C7: ISO-09, ISO-10, NIST-07 | D7: Training | E7: Adequate | F7: HR / Security
A8: EV-007 | B8: Access Control Policy | C8: A-02, A-03, NIST-06 | D8: Policy / Control | E8: Adequate | F8: IT / Security
A9: EV-008 | B9: Incident Response Policy | C9: A-04, A-05, A-06, NIST-09 | D9: Policy | E9: Strong | F9: Security Operations
A10: EV-009 | B10: Incident Tabletop Exercise | C10: A-04, A-06, NIST-09 | D10: Exercise | E10: Strong | F10: Security Operations
A11: EV-010 | B11: Evidence Handling Procedures | C11: A-07 | D11: Procedure | E11: Limited | F11: Security Operations
A12: EV-011 | B12: BIA | C12: A-08, NIST-10 | D12: Business Continuity | E12: Strong | F12: Business Continuity
... A21: EV-020 | B21: Malware Analysis Report | C21: P5 | D21: Investigation | E21: Strong | F21: Security Operations

Sheet Assessment Metadata
A1: Assessment Information
A2: Field | B2: Value
A3: Assessment Reference | B3: AAX-COMP-2026-001
A4: Organization | B4: Axiom AI Technologies
A5: Assessment Type | B5: Internal Compliance Assessment
A6: Assessment Period | B6: October 2026
A7: Primary Framework | B7: ISO/IEC 27001:2022
A8: Supporting Frameworks | B8: NIST CSF 2.0; NIST SP 800-53
A9: Scope | B9: Axiom AI ISMS and supporting cybersecurity processes
A10: Assessor | B10: Security / GRC
A11: Control Owners | B11: Assigned by control domain
A12: Classification | B12: Internal Use — Portfolio Case Study
A13: Status | B13: In Progress
A14: Next Review | B14: October 2027
A16: Compliance Status Definitions
A17: Term | B17: Definition
A18: Compliant | B18: Requirement is implemented and sufficient evidence exists to demonstrate effectiveness.
A19: Partially Compliant | B19: Requirement is substantially addressed, but one or more gaps, inconsistencies, or evidence weaknesses remain.
A20: Non-Compliant | B20: Requirement has not been adequately implemented or evidence is insufficient to demonstrate implementation.
A21: Not Applicable | B21: Requirement has been assessed and determined not applicable to the defined scope.
A22: Under Review | B22: Assessment remains open pending additional evidence or validation.
A24: Evidence Ratings
A25: Term | B25: Definition
A26: Strong | B26: Clear, current, approved, and traceable evidence.
A27: Adequate | B27: Evidence exists and generally supports implementation, but minor improvements may be needed.
A28: Limited | B28: Evidence exists but is incomplete, inconsistent, or insufficient for strong assurance.
A29: Missing | B29: Required evidence was not available.
A31: Risk Ratings
A32: Term | B32: Definition
A33: Critical | B33: Immediate and potentially severe organizational impact.
A34: High | B34: Significant impact requiring prioritized remediation.
A35: Moderate | B35: Meaningful control or compliance weakness requiring planned remediation.
A36: Low | B36: Limited residual risk or minor improvement opportunity.
A38: Assessment Methodology
A39: Traceability chain: Requirement → Control / Process → Evidence → Compliance Status → Risk → Finding → Remediation → Validation
A40: 1 | B40: Identify applicable requirements.
A41: 2 | B41: Map each requirement to an Axiom control or process.
A42: 3 | B42: Identify supporting policies and artifacts.
A43: 4 | B43: Review available evidence.
A44: 5 | B44: Assign an evidence rating.
...
